Workbook
Name الألقاب: data!$L$2:$L$6
Name القسم: data!$O$2:$O$29
Name الكليات: data!$A$2:$A$11
Name المهام: data!$E$2:$E$9
Name ساعات: data!$J$1
Name مراكز: data!$Q$2:$Q$4
Name نصاب: البيانات!$F$1

Sheet البيانات
A1: استمارة الساعات الزائدة للثابتين للفصل الثاني للعام الجامعي 2025 -2026 م | F1: =IFERROR(INDEX(data!$L$2:$M$6,MATCH(C7,data!$L$2:$L$6,0),2),"") | G1: =IFERROR(INDEX(data!$E$2:$F$9,MATCH(C5,data!$E$2:$E$9,0),2),"") | H1: =IF(D6<>"",J1,"t") -> t | I1: =COUNTA(القسم)+1 -> 29 | J1: =IFERROR(INDEX(data!$O$2:$O$29,MATCH(D6,data!$O$2:$O$29,0),1),"f") -> f | L1: =IF(C5="رئيس قسم",CONCATENATE(C5," ",C6),IF(C5="مدير مركز",CONCATENATE(C5," ",D5),IF(C5="عميد الكلية",CONCATENATE("عميد كلية ",C3),IF(C5="نائب رئيس الجامعة",L2,C5)))) -> 0 | N1: =IF(C5="مدير مركز","مركز","") | O1: =IF(M1<>"",M1,L1) -> 0 | V1: نائب رئيس الجامعة للدراسات العليا والبحث العلمي | W1: مودي
A2: ادخال البيانات الشخصية | L2: =INDEX(V1:W3,MATCH(RIGHT(C4,4),W1:W3,0),1) -> #N/A | V2: نائب رئيس الجامعة للشئون الأكاديمية | W2: شهاب
B3: الكلية: | V3: نائب رئيس الجامعة لشئون الطلاب | W3: يلان
B4: الاسم: | D4: =IF(C5="مدير مركز","اختر اسم المركز","")
B5: المهام الإدارية :
B6: القسم:
B7: اللقب العلمي :

Sheet الفصل الثاني
A1: أستمارة احتساب الساعات الزائدة لأعضاء هيئة التدريس ومساعديهم للفصل الدراسي الثاني للعام 2025- 2026 م
A2: الكلية : | C2: =IF(البيانات!C3<>"",البيانات!C3,"") | E2: القسم : | G2: =IF(البيانات!C6<>"",البيانات!C6,"") | J2: عدد أسابيع الفصل الدراسي 14 أسبوع
B3: الاسم : | C3: =IF(البيانات!C4<>"",البيانات!C4,"") | I3: المهام الإدارية : | K3: =IF(IF(البيانات!O1<>"",البيانات!O1,"")=0,"",IF(البيانات!O1<>"",البيانات!O1))
A6: الأسبوع | B6: اليوم والتاريخ | D6: عدد الساعات | I6: تعبأفي حالة الدمج مع الشعب فقط | K6: المقرر الدراسي | L6: الكلية التي نفذت بها الساعات
D7: نظري | E7: عملي | F7: إشراف عملي | G7: إشراف م/تخرج | H7: إجمالي س/ مستحقة | I7: الاقسام / المستويات (الأخرى المدمجة) | J7: عدد الطلاب في حالة الدمج و في حاله التربية العملية
A8: الأول | B8: الأحد | C8: 2026/1/11م بدء الفصل الدراسي الثاني | H8: =SUM(D8:G8) -> 0
H9: =SUM(D9:G9) -> 0
H10: =SUM(D10:G10) -> 0
H11: =SUM(D11:G11) -> 0
B12: الإثنين | C12: 46034 | H12: =SUM(D12:G12) -> 0
H13: =SUM(D13:G13) -> 0
H14: =SUM(D14:G14) -> 0
H15: =SUM(D15:G15) -> 0
B16: الثلاثاء | C16: 46035 | H16: =SUM(D16:G16) -> 0
H17: =SUM(D17:G17) -> 0
H18: =SUM(D18:G18) -> 0
H19: =SUM(D19:G19) -> 0
B20: الأربعاء | C20: 46036 | H20: =SUM(D20:G20) -> 0
H21: =SUM(D21:G21) -> 0
H22: =SUM(D22:G22) -> 0
H23: =SUM(D23:G23) -> 0
B24: الخميس | C24: 46037 | H24: =SUM(D24:G24) -> 0
H25: =SUM(D25:G25) -> 0
H26: =SUM(D26:G26) -> 0
H27: =SUM(D27:G27) -> 0
B28: المهام الادارية | D28: =IF(ساعات<>"",ساعات,"") | H28: =SUM(D28:G28) -> 0
B29: اجمالي ساعات الغياب | D29: ='الغياب الاسبوعي'!D3 -> 0 | H29: =SUM(D29:G29) -> 0
B30: مجموع ساعات الأسبوع | D30: =SUM(D8:D28) -> 0 | E30: =SUM(E8:E28) -> 0 | F30: =SUM(F8:F28) -> 0 | G30: =SUM(G8:G28) -> 0 | H30: =SUM(H8:H28)-H29 -> 0
B31: مجموع الساعات الزائدة في الأسبوع | H31: =IF(H30>نصاب,H30-نصاب,0) -> 0
A32: الثاني | B32: الأحد | C32: 46040 | D32: =IF(D8="","",D8) | E32: =IF(E8="","",E8) | F32: =IF(F8="","",F8) | G32: =IF(G8="","",G8) | H32: =SUM(D32:G32) -> 0 | I32: =IF(I8="","",I8) | J32: =IF(J8="","",J8) | K32: =IF(K8="","",K8) | L32: =IF(L8="","",L8)
D33: =IF(D9="","",D9) | E33: =IF(E9="","",E9) | F33: =IF(F9="","",F9) | G33: =IF(G9="","",G9) | H33: =SUM(D33:G33) -> 0 | I33: =IF(I9="","",I9) | J33: =IF(J9="","",J9) | K33: =IF(K9="","",K9) | L33: =IF(L9="","",L9)
D34: =IF(D10="","",D10) | E34: =IF(E10="","",E10) | F34: =IF(F10="","",F10) | G34: =IF(G10="","",G10) | H34: =SUM(D34:G34) -> 0 | I34: =IF(I10="","",I10) | J34: =IF(J10="","",J10) | K34: =IF(K10="","",K10) | L34: =IF(L10="","",L10)
D35: =IF(D11="","",D11) | E35: =IF(E11="","",E11) | F35: =IF(F11="","",F11) | G35: =IF(G11="","",G11) | H35: =SUM(D35:G35) -> 0 | I35: =IF(I11="","",I11) | J35: =IF(J11="","",J11) | K35: =IF(K11="","",K11) | L35: =IF(L11="","",L11)
B36: الإثنين | C36: 46041 | D36: =IF(D12="","",D12) | E36: =IF(E12="","",E12) | F36: =IF(F12="","",F12) | G36: =IF(G12="","",G12) | H36: =SUM(D36:G36) -> 0 | I36: =IF(I12="","",I12) | J36: =IF(J12="","",J12) | K36: =IF(K12="","",K12) | L36: =IF(L12="","",L12)
D37: =IF(D13="","",D13) | E37: =IF(E13="","",E13) | F37: =IF(F13="","",F13) | G37: =IF(G13="","",G13) | H37: =SUM(D37:G37) -> 0 | I37: =IF(I13="","",I13) | J37: =IF(J13="","",J13) | K37: =IF(K13="","",K13) | L37: =IF(L13="","",L13)
D38: =IF(D14="","",D14) | E38: =IF(E14="","",E14) | F38: =IF(F14="","",F14) | G38: =IF(G14="","",G14) | H38: =SUM(D38:G38) -> 0 | I38: =IF(I14="","",I14) | J38: =IF(J14="","",J14) | K38: =IF(K14="","",K14) | L38: =IF(L14="","",L14)
D39: =IF(D15="","",D15) | E39: =IF(E15="","",E15) | F39: =IF(F15="","",F15) | G39: =IF(G15="","",G15) | H39: =SUM(D39:G39) -> 0 | I39: =IF(I15="","",I15) | J39: =IF(J15="","",J15) | K39: =IF(K15="","",K15) | L39: =IF(L15="","",L15)
B40: الثلاثاء | C40: 46042 | D40: =IF(D16="","",D16) | E40: =IF(E16="","",E16) | F40: =IF(F16="","",F16) | G40: =IF(G16="","",G16) | H40: =SUM(D40:G40) -> 0 | I40: =IF(I16="","",I16) | J40: =IF(J16="","",J16) | K40: =IF(K16="","",K16) | L40: =IF(L16="","",L16)
D41: =IF(D17="","",D17) | E41: =IF(E17="","",E17) | F41: =IF(F17="","",F17) | G41: =IF(G17="","",G17) | H41: =SUM(D41:G41) -> 0 | I41: =IF(I17="","",I17) | J41: =IF(J17="","",J17) | K41: =IF(K17="","",K17) | L41: =IF(L17="","",L17)
D42: =IF(D18="","",D18) | E42: =IF(E18="","",E18) | F42: =IF(F18="","",F18) | G42: =IF(G18="","",G18) | H42: =SUM(D42:G42) -> 0 | I42: =IF(I18="","",I18) | J42: =IF(J18="","",J18) | K42: =IF(K18="","",K18) | L42: =IF(L18="","",L18)
...

Sheet الغياب الاسبوعي
A1: استمارة ساعات الغياب خلال الفصل الدراسي الثاني للعام الجامعي 2025-2026م
A2: الأسبوع | B2: بداية الأسبوع | C2: نهاية الأسبوع | D2: عدد ساعات الغياب في الاسبوع | E2: ملاحظات
A3: الأول | B3: 46033 | C3: 46037
A4: الثاني | B4: 46040 | C4: 46044
A5: الثالث | B5: 46047 | C5: 46051
A6: الرابع | B6: 46054 | C6: 46058
A7: الخامس | B7: 46061 | C7: 46065
A8: السادس | B8: 46068 | C8: 46070
A9: السابع | B9: 46110 | C9: 46114
A10: الثامن | B10: 46117 | C10: 46121
A11: التاسع | B11: 46124 | C11: 46128
A12: العاشر | B12: 46131 | C12: 46135
A13: الحادي عشر | B13: 46138 | C13: 46142
A14: الثاني عشر | B14: 46146 | C14: 46149
... A16: الرابع عشر | B16: 46159 | C16: 46163
A19: رئيس القسم: | B19: ='الفصل الثاني'!D347 -> 0 | D19: التوقيع: ............................ | E19: التاريخ : .........................
A20: نائب العميد الأكاديمي: | B20: ='الفصل الثاني'!D348 -> 0 | D20: التوقيع: ............................ | E20: التاريخ : .........................
A21: عميد الكلية : | B21: ='الفصل الثاني'!D349 -> 0 | D21: التوقيع: ............................ | E21: التاريخ : .........................

Sheet data
A1: الكليات | E1: المهام | F1: الساعات | J1: =IFERROR(INDEX(data!$E$2:$F$9,MATCH(البيانات!C5,data!$E$2:$E$9,0),2),"") | L1: الألقاب | M1: النصاب | O1: القسم | Q1: مراكز
A2: التربية | E2: رئيس الجامعة | F2: 7 | L2: أستاذ | M2: 8 | O2: اللغة العربية | Q2: التطوير الأكاديمي وضمان الجودة
A3: البنات | E3: نائب رئيس الجامعة | F3: 6 | L3: أستاذ مشارك | M3: 10 | O3: اللغة الانجليزية | Q3: تقنية المعلومات
A4: الأداب واللغات | E4: عميد الكلية | F4: 5 | L4: أستاذ مساعد | M4: 12 | O4: الرياضيات | Q4: اللغات و خدمة المجتمع
A5: الحاسبات | E5: مدير مركز | F5: 5 | L5: مدرس | M5: 13 | O5: الفيزياء
A6: العلوم الإدارية | E6: مدير مركز نحل العسل | F6: 4 | L6: معيد | M6: 13 | O6: الكيمياء
A7: الطب والعلوم الصحية | E7: مدير مركز النخيل والتمور | F7: 4 | O7: المناهج و طرق التدريس
A8: الحقوق والعلوم الإنسانية | E8: نائب عميد الكلية | F8: 4 | O8: التاريخ
A9: علوم الرياضة | E9: رئيس قسم | F9: 3 | O9: الجغرافيا
A10: الزراعة والأغذية | O10: امن المعلومات
A11: التعليم عن بعد | O11: علوم الحاسب
A12: الزراعة والأغذية | O12: المحاسبة
C13: التربية | D13: البنات | E13: الأداب واللغات | F13: الحاسبات | G13: العلوم الإدارية | H13: الزراعة والأغذية | I13: علوم الرياضة | J13: الحقوق والعلوم الإنسانية | K13: الطب والعلوم الصحية | M13: =البيانات!C3 -> 0 | O13: تقنية المعلومات
C14: الرياضيات | D14: رياض الأطفال | E14: اللغة العربية | F14: امن المعلومات | G14: إدارة الأعمال | H14: الزراعة و الأغذية | I14: التدريب والصحة الرياضية | J14: القانون | K14: الطب البشري | M14: =IF($M$13=$C$13,C14,IF($M$13=$D$13,D14,IF($M$13=$E$13,E14,IF($M$13=$F$13,F14,IF($M$13=$G$13,G14,IF($M$13=$H$13,H14,IF($M$13=$I$13,I14,IF($M$13=$J$13,J14,IF($M$13=$K$13,K14,""))))))))) | O14: إدارة الأعمال
C15: الفيزياء | D15: اللغة الانجليزية | E15: اللغة الانجليزية | F15: علوم الحاسب | G15: العلوم المالية و المصرفية | H15: الإنتاج النباتي | I15: المناهج والتدريس الرياضي | J15: اللغة الإنجليزية | K15: ="" | M15: =IF($M$13=$C$13,C15,IF($M$13=$D$13,D15,IF($M$13=$E$13,E15,IF($M$13=$F$13,F15,IF($M$13=$G$13,G15,IF($M$13=$H$13,H15,IF($M$13=$I$13,I15,IF($M$13=$J$13,J15,IF($M$13=$K$13,K15,""))))))))) | O15: الزراعة و الأغذية
C16: الكيمياء | D16: التربية الخاصة | E16: الدراسات الإسلامية | F16: تقنية المعلومات | G16: المحاسبة | H16: ="" | I16: ="" | J16: ="" | K16: ="" | M16: =IF($M$13=$C$13,C16,IF($M$13=$D$13,D16,IF($M$13=$E$13,E16,IF($M$13=$F$13,F16,IF($M$13=$G$13,G16,IF($M$13=$H$13,H16,IF($M$13=$I$13,I16,IF($M$13=$J$13,J16,IF($M$13=$K$13,K16,""))))))))) | O16: العلوم المالية و المصرفية
C17: المناهج و طرق التدريس | D17: ="" | E17: ="" | F17: ="" | G17: ="" | H17: ="" | I17: ="" | J17: ="" | K17: ="" | M17: =IF($M$13=$C$13,C17,IF($M$13=$D$13,D17,IF($M$13=$E$13,E17,IF($M$13=$F$13,F17,IF($M$13=$G$13,G17,IF($M$13=$H$13,H17,IF($M$13=$I$13,I17,IF($M$13=$J$13,J17,IF($M$13=$K$13,K17,""))))))))) | O17: الدراسات الإسلامية
C18: التاريخ | D18: ="" | E18: ="" | F18: ="" | G18: ="" | H18: ="" | I18: ="" | J18: ="" | K18: ="" | M18: =IF($M$13=$C$13,C18,IF($M$13=$D$13,D18,IF($M$13=$E$13,E18,IF($M$13=$F$13,F18,IF($M$13=$G$13,G18,IF($M$13=$H$13,H18,IF($M$13=$I$13,I18,IF($M$13=$J$13,J18,IF($M$13=$K$13,K18,""))))))))) | O18: اللغة الانجليزية
C19: الجغرافيا | D19: ="" | E19: ="" | F19: ="" | G19: ="" | H19: ="" | I19: ="" | J19: ="" | K19: ="" | M19: =IF($M$13=$C$13,C19,IF($M$13=$D$13,D19,IF($M$13=$E$13,E19,IF($M$13=$F$13,F19,IF($M$13=$G$13,G19,IF($M$13=$H$13,H19,IF($M$13=$I$13,I19,IF($M$13=$J$13,J19,IF($M$13=$K$13,K19,""))))))))) | O19: رياض الأطفال
C20: العلوم التربوية والنفسية | D20: ="" | E20: ="" | F20: ="" | G20: ="" | H20: ="" | I20: ="" | J20: ="" | K20: ="" | M20: =IF($M$13=$C$13,C20,IF($M$13=$D$13,D20,IF($M$13=$E$13,E20,IF($M$13=$F$13,F20,IF($M$13=$G$13,G20,IF($M$13=$H$13,H20,IF($M$13=$I$13,I20,IF($M$13=$J$13,J20,IF($M$13=$K$13,K20,""))))))))) | O20: الطب البشري
O21: الدراسات الإسلامية
O22: اللغة العربية
O23: اللغة الانجليزية
O24: المحاسبة
O25: إدارة الأعمال
O26: رياض الأطفال
O27: العلوم التربوية والنفسية
O28: التربية البدنية و الرياضية
O29: إضافة قسم جديد

Sheet يونيو 2022 م  
A1: أستمارة احتساب الساعات الزائدة لأعضاء هيئة التدريس ومساعديهم للفصل الراسي الثاني للعام 2021- 2022 م
A2: الكلية : | C2: =IF(البيانات!C3<>"",البيانات!C3,"") | E2: القسم : | G2: =IF(البيانات!C6<>"",البيانات!C6,"") | J2: الشهر والعام الميلادي : يونيو2022م
B3: الاسم : | C3: =IF(البيانات!C4<>"",البيانات!C4,"") | I3: المهام الإدارية : | K3: =IF(IF(البيانات!O1<>"",البيانات!O1,"")=0,"",IF(البيانات!O1<>"",البيانات!O1))
A6: الأسبوع | B6: اليوم والتاريخ | D6: عدد الساعات | I6: تعبأفي حالة الدمج مع الشعب فقط | K6: المقرر الدراسي | L6: الكلية التي نفذت بها الساعات
D7: نظري | E7: عملي | F7: إشراف عملي | G7: إشراف م/تخرج | H7: إجمالي س/ مستحقة | I7: الاقسام / المستويات (الأخرى المدمجة) | J7: عدد الطلاب في حالة الدمج و في حاله التربية العملية
A8: الأول | B8: السبت | C8: 44709 | H8: =SUM(D8:G8) -> 0
H9: =SUM(D9:G9) -> 0
H10: =SUM(D10:G10) -> 0
B11: الاحد | C11: 44710 | H11: =SUM(D11:G11) -> 0
H12: =SUM(D12:G12) -> 0
H13: =SUM(D13:G13) -> 0
B14: الإثنين | C14: 44711 | H14: =SUM(D14:G14) -> 0
H15: =SUM(D15:G15) -> 0
H16: =SUM(D16:G16) -> 0
B17: الثلاثاء | C17: 44712 | H17: =SUM(D17:G17) -> 0
H18: =SUM(D18:G18) -> 0
H19: =SUM(D19:G19) -> 0
B20: الأربعاء | C20: 44713 | H20: =SUM(D20:G20) -> 0
H21: =SUM(D21:G21) -> 0
H22: =SUM(D22:G22) -> 0
B23: الخميس | C23: 44714 | H23: =SUM(D23:G23) -> 0
H24: =SUM(D24:G24) -> 0
H25: =SUM(D25:G25) -> 0
B26: المهام الادارية | D26: =IF(ساعات<>"",ساعات,"") | H26: =SUM(D26:G26) -> 0
B27: مجموع ساعات الأسبوع | D27: =SUM(D8:D26) -> 0 | E27: =SUM(E8:E26) -> 0 | F27: =SUM(F8:F26) -> 0 | G27: =SUM(G8:G26) -> 0 | H27: =SUM(H8:H26) -> 0
B28: مجموع الساعات الزائدة في الأسبوع | H28: =IF(H27>نصاب,H27-نصاب,0) -> 0
A29: الثــاني | B29: السبت | C29: 44716 | H29: =SUM(D29:G29) -> 0
H30: =SUM(D30:G30) -> 0
H31: =SUM(D31:G31) -> 0
B32: الأحد | C32: 44717 | H32: =SUM(D32:G32) -> 0
H33: =SUM(D33:G33) -> 0
H34: =SUM(D34:G34) -> 0
B35: الإثنين | C35: 44718 | H35: =SUM(D35:G35) -> 0
H36: =SUM(D36:G36) -> 0
H37: =SUM(D37:G37) -> 0
B38: الثلاثاء | C38: 44719 | H38: =SUM(D38:G38) -> 0
H39: =SUM(D39:G39) -> 0
H40: =SUM(D40:G40) -> 0
B41: الأربعاء | C41: 44720 | H41: =SUM(D41:G41) -> 0
H42: =SUM(D42:G42) -> 0
...
